Workbook

Sheet How to Use
B2: AI Agent Use Case Discovery & Prioritization Workbook
B3: From The Agentic Enterprise Strategy — agenticstrategylab.com
B5: What This Workbook Does
B7: This workbook takes you from "AI could probably help somewhere" to a specific, justified decision. It works for a founder choosing their first AI feature, a product team evaluating their next initiative, an architect assessing feasibility, or a hackathon team picking a project worth the effort.
B9: The Five Tabs — One Decision Journey
B11: 1. Discovery | C11: Surface real problems using 10 agent-specific prompts. Each targets a pattern where the Sense→Think→Plan→Act loop outperforms traditional automation.
B12: 2. Scoring | C12: Evaluate candidates across 10 weighted dimensions (5 feasibility + 5 impact). Descriptive dropdowns guide each score. Auto-calculates composites and ranks.
B13: 3. Risk Assessment | C13: Assess your top candidates across 7 risk dimensions — including 3 agent-specific risks (hallucination, integration fragility, context drift). Maps to autonomy level.
B14: 4. Prioritization Matrix | C14: Auto-generated ranked table. Combines feasibility, impact, risk, and recommendation. Nothing to fill in — all formulas.
B15: 5. Selection Brief | C15: Structured one-page decision document for your winning use case: problem, agent approach, ROI estimate, and GO/NO-GO decision.
B18: How Scoring Works
B20: Three scoring areas, two directions. For Feasibility and Impact, higher is better — push numbers up. For Risk, lower is better — push numbers down. The composite score (50% Feasibility + 50% Impact) drives the recommendation. Risk is assessed separately and determines the autonomy level.
B22: FEASIBILITY | C22: IMPACT | D22: RISK
B23: ⬆ Higher = Better 5 = easy to build 1 = hard to build | C23: ⬆ Higher = Better 5 = transformative value 1 = minimal value | D23: ⬇ Lower = Better 1 = minimal risk 5 = severe risk
B24: Recommendations: | C24: Score 4.0+ = ✅ Pursue | 3.0–3.9 = 🔍 Investigate | 2.0–2.9 = ⏸️ Park | Below 2.0 = ❌ Drop
B27: Scoring Dimensions Reference
B29: Dimension | C29: What It Measures | D29: ⬆ Score 1 → Score 5
B30: F1: Strategic Alignment (25%) | C30: Does this map to a real business goal or KPI? Score based on how directly this supports a stated organizational priority. | D30: 1 = Nice to have, no sponsor 2 = Loosely connected to a goal 3 = Supports a known business goal 4 = Directly tied to a priority 5 = Top-3 strategic initiative
B31: F2: Data Readiness (20%) | C31: Do the data sources, APIs, and integrations the agent needs exist today? | D31: 1 = Data doesn't exist yet 2 = Exists but needs major cleanup 3 = Some integration work needed 4 = Accessible, APIs mostly ready 5 = Clean, APIs ready, tested
B32: F3: Technical Feasibility (25%) | C32: Can you build this with available tools? Consider: do MCP servers exist? Can LLMs handle the reasoning? Is the task well-scoped for an agent loop? | D32: 1 = Requires capabilities that don't exist 2 = Significant custom R&D needed 3 = Buildable with new tools or skills 4 = Buildable with current tools 5 = Could prototype in 1–2 weeks
B33: F4: Autonomy Fit (15%) | C33: Is the right level of agent independence achievable AND safe? Match the autonomy level to the risk. | D33: 1 = Needs autonomy but risk is severe 2 = Autonomy/risk mismatch, hard to govern 3 = Moderate autonomy, manageable oversight 4 = Good fit with clear guardrails 5 = Low-risk task, full autonomy is safe
B34: F5: Time to Value (15%) | C34: How quickly will this deliver real value — actual time saved, errors reduced, or revenue generated? Not a demo — real value. | D34: 1 = 6+ months before anyone sees value 2 = 3–6 months to real value 3 = 1–3 months to real value 4 = Weeks to first real value 5 = Value realized within days
B36: Dimension | C36: What It Measures | D36: ⬆ Score 1 → Score 5
B37: I1: Time Saved (25%) | C37: How many person-hours per week does this eliminate or significantly reduce across all affected people? | D37: 1 = Under 2 hrs/week saved 2 = 2–5 hrs/week saved 3 = 5–15 hrs/week saved 4 = 15–30 hrs/week saved 5 = 30+ hrs/week saved
B38: I2: Cost Reduction (20%) | C38: What's the direct cost saving — labor, errors, rework, penalties? Think annual impact. | D38: 1 = Negligible savings 2 = Under $25K/year 3 = $25K–$75K/year 4 = $75K–$200K/year 5 = Over $200K/year
B39: I3: Error Reduction (20%) | C39: How much does this reduce mistakes and their consequences? Consider both error rate and cost per error. | D39: 1 = Errors rare and inconsequential 2 = Occasional errors, minor impact 3 = Regular errors, moderate cost 4 = Frequent errors, real consequences 5 = High error rate, severe consequences
B40: I4: Revenue Potential (15%) | C40: Does this agent enable new revenue or accelerate existing revenue? Not every use case scores high here — cost savings alone can justify. | D40: 1 = No revenue connection 2 = Indirect revenue support 3 = Enables faster revenue cycles 4 = Directly accelerates revenue 5 = Opens entirely new revenue streams
B41: I5: Scale Leverage (20%) | C41: Does value increase with more users or volume without proportional cost? One-time build, many-time benefit. | D41: 1 = Benefits one person only 2 = Benefits a small team (2–5) 3 = Benefits a department (10–50) 4 = Benefits across the organization 5 = Scales to 100+ users or processes
... B50: R7: Context & Skill Drift | C50: Will the agent's context, skills, and memory stay accurate as the business changes over time? | D50: 1 = Stable environment, rarely changes 2 = Changes quarterly, predictable 3 = Changes monthly, manageable 4 = Changes frequently, hard to track 5 = Constant flux, agent breaks often
B53: Conventions
B55: Blue text on light blue cells | C55: Your inputs — fill these in
B56: Black bold text | C56: Formulas — auto-calculated, don't edit
B57: Gray italic text | C57: Guidance, examples, and interpretation notes

Sheet Discovery
B2: Step 1: Use Case Discovery
B3: Identify problems that specifically need an AI agent — not just any automation.
B4: Each prompt targets a pattern where the Sense → Think → Plan → Act loop outperforms traditional tools.
B6: How to use this tab: | D6: Not every problem needs an AI agent. A lot of what feels like "AI could help here" is actually a better Zapier workflow, a script, or honestly, a better spreadsheet. This tab helps you tell the difference. Each of the 10 patterns below targets a specific shape of problem where agents genuinely outperform traditional tools. The test is simple: does the problem require judgment, synthesis across multiple sources, handling messy unstructured inputs, or coordinating multiple steps where the next action depends on what just happened? If yes — you're looking at an agent. If it's a clean trigger → action, it's automation. Both are fine. But they're different investments with different architectures. For each pattern, you'll find: the discovery question (to spark recognition), space for your answer, a concrete example, why this specifically needs an agent and not automation, the builder's arsenal (which tools fit), the building blocks involved (from the Primer), and a pattern match checklist — 4 signals that confirm you're looking at this pattern. Start by reading through all 10 patterns. Some will immediately remind you of a process you've seen. Write those down — even rough notes help. Then scroll to the candidate table at the bottom, name your strongest use cases, and associate each with a pattern. That pattern association matters — it tells you which building blocks the agent needs and which architecture fits.
B8: 10 Agent-Specific Opportunity Patterns
B10: P1 | C10: Judgment-Heavy Triage | D10: Do you or your team regularly review items — tickets, applications, requests, messages, leads — and make a judgment call on each one that can't be reduced to a simple rule?
C11: Your answer:
C12: Example: | D12: e.g., Support agents read each ticket, assess urgency and sentiment, and decide routing and priority. Or: loan officers review applications weighing 15+ factors that vary case by case.
C13: Why an agent: | D13: The decision logic is fuzzy and context-dependent. Every case is slightly different. Traditional rules engines break on ambiguity — an LLM reasons through edge cases the way a human would.
C14: Arsenal: | D14: Claude.ai or ChatGPT (reasoning) → Claude Code or Cursor (build) → MCP (connect to ticketing/CRM) → Skills (triage SOP) → LangSmith (monitor decisions)
C15: Blocks: | D15: LLM + Loop + Tools (MCP) + Skills + Guardrails
C16: What to look for: | D16: high volume (50+ items/day), decisions take 5+ minutes each, experienced staff disagree on ~15% of cases, or new hires take weeks to learn the judgment.
C17: Pattern match: | D17: ✅ You have this pattern if: (1) Decisions can't be reduced to if/then rules (2) Volume is 50+ items/day (3) Experienced staff disagree ~15% of the time (4) New hires take weeks to learn the judgment | F17: Here's what it means: take the same ticket, application, or request and show it to two experienced people on your team — people who've been doing this job for years. If they'd route it differently, prioritize it differently, or make a different call roughly 15% of the time, that tells you something important: the decision logic is inherently ambiguous. It's not that one person is wrong — it's that reasonable experts interpret the same inputs differently based on subtle context clues.
B18: P2 | C18: Multi-Source Research & Synthesis | D18: Do you regularly pull information from 3 or more different sources, piece it together, and produce a summary, analysis, or recommendation?
C19: Your answer:
C20: Example: | D20: e.g., Analysts pull from CRM, market data, news, and internal docs to build a weekly executive brief. Or: due diligence teams compile findings from 10+ sources into a structured assessment.
C21: Why an agent: | D21: Simple aggregation tools just collect data. An agent reasons across unstructured sources — comparing, weighing contradictions, and producing original analysis. RAG + reasoning is what makes this agentic.
C22: Arsenal: | D22: Perplexity (web research) → Claude.ai (synthesis) → MCP (connect to CRM, Drive, Slack) → Cursor or Claude Code (build) → Workato or n8n (schedule recurring runs)
C23: Blocks: | D23: LLM + Loop + Tools (MCP) + Context + Memory
C24: What to look for: | D24: the research takes 2+ hours, spans 3+ systems, the output is a narrative (not just numbers), and the same person does it weekly.
C25: Pattern match: | D25: ✅ You have this pattern if: (1) Research spans 3+ different sources/systems (2) Output is a narrative, not just a data dump (3) Research takes 2+ hours per report (4) Synthesis requires weighing conflicting information
B26: P3 | C26: Unstructured-to-Structured Transformation | D26: Do you deal with messy, inconsistent inputs — emails, PDFs, invoices, forms, varied documents — that need to be turned into structured data or action?
C27: Your answer:
C28: Example: | D28: e.g., Accounts payable reads invoices in 50 different formats and enters vendor/amount/date into the ERP. Or: HR reads resumes in varied layouts and extracts skills and experience into a database.
C29: Why an agent: | D29: Traditional parsers and OCR break on format variation. An LLM handles any layout, any wording, and still extracts the right fields. The agent loop self-corrects when extraction confidence is low.
C30: Arsenal: | D30: Claude.ai (multimodal — reads PDFs/images) → Claude Code (build extraction pipeline) → MCP (connect to ERP/database) → LangGraph (multi-step validation) → Skills (extraction rules per doc type)
C31: Blocks: | D31: LLM (multimodal) + Loop + Tools (MCP) + Skills
C32: What to look for: | D32: input formats vary significantly, volume is 20+/day, current error rate exceeds 5%, or you've tried OCR/parser solutions and they failed on edge cases.
C33: Pattern match: | D33: ✅ You have this pattern if: (1) No two inputs look the same (varied formats) (2) Volume is 20+ items/day (3) Current process has 5%+ error rate (4) Traditional parsers/OCR break on the format variation
B34: P4 | C34: Context-Aware Communication | D34: Do you write personalized messages, proposals, or documents where each one needs to reflect the recipient's specific history, context, and preferences?
C35: Your answer:
C36: Example: | D36: e.g., Account managers write renewal proposals tailored to each client's usage and contract terms. Or: support writes follow-ups referencing the customer's full issue history and tone preferences.
C37: Why an agent: | D37: Template-based mail merge can't adapt to context. The agent pulls history from CRM/email, reasons about what matters for this person, and generates output that feels human — not formulaic. Memory and context are the key differentiators.
C38: Arsenal: | D38: Claude.ai (drafting) → MCP (CRM, email, calendar, past interactions) → Claude Code or Cursor (build) → Memory (past communications) → Context files (tone, brand voice, templates)
C39: Blocks: | D39: LLM + Context + Memory + Tools (MCP) + Skills
C40: What to look for: | D40: personalization takes 15+ minutes per message, there are 10+ messages/day, the quality varies by writer, or you've tried templates and recipients notice they're generic.
C41: Pattern match: | D41: ✅ You have this pattern if: (1) Personalization takes 15+ min per message (2) Volume is 10+ messages/day (3) Quality drops when you rush (4) Each message needs to reflect recipient's specific history and context
B42: P5 | C42: Multi-Step Workflow Orchestration | D42: Is there a process that requires multiple steps across different tools — where the right next step depends on what happened in the previous step?
C43: Your answer:
C44: Example: | D44: e.g., Employee onboarding: create accounts → assign permissions → schedule orientation → generate welcome packet → notify manager — each step conditional on role, department, and location. Or: incident response: detect → classify → notify → create ticket → gather logs → draft RCA.
...

Sheet Scoring
B2: Step 2: Feasibility & Impact Scoring
B3: Score each use case from your Discovery tab on every dimension below. Use the 1–5 scale. If you're unsure, that's usually a 3.
B5: For each dimension, ask yourself: "Based on what I learned in the Discovery prompts, how would I rate this use case?" The dimension definitions are in the How to Use tab — refer to them if you're unsure what a score means. You don't need to score all 10 candidates. Focus on the ones that felt most promising during Discovery. The workbook will auto-calculate weighted scores, rank your candidates, and give you a recommendation.
B6: Scoring: 1 = Very Low/Poor | 2 = Low/Poor | 3 = Moderate | 4 = High/Good | 5 = Very High/Excellent
B8: # | C8: Dimension | D8: Weight | E8: Use Case 1 | F8: Use Case 2 | G8: Use Case 3 | H8: Use Case 4 | I8: Use Case 5 | J8: Use Case 6 | K8: Use Case 7 | L8: Use Case 8 | M8: Use Case 9 | N8: Use Case 10
C9: (Name from Discovery) | E9: Stock Market Guide | F9: News Letter - Daily Quotes | G9: Real Estate Searcher | H9: Real Estate Franchisee | I9: Personal Calendar Aid | J9: Travel Agent | K9: =IF(Discovery!C101<>"",Discovery!C101,"—") -> — | L9: =IF(Discovery!C102<>"",Discovery!C102,"—") -> — | M9: =IF(Discovery!C103<>"",Discovery!C103,"—") -> — | N9: =IF(Discovery!C104<>"",Discovery!C104,"—") -> —
B11: FEASIBILITY — Can we build it?
B12: F1 | C12: Strategic Alignment | D12: 0.25 | E12: 2 — Loosely connected | F12: 4 — Tied to a priority | G12: 3 — Supports a business goal | H12: 5 — Top-3 initiative | I12: 5 — Top-3 initiative | J12: 5 — Top-3 initiative
B13: F2 | C13: Data Readiness | D13: 0.2 | E13: 4 — APIs mostly ready | F13: 5 — Clean and ready | G13: 3 — Some integration needed | H13: 2 — Needs major cleanup | I13: 3 — Some integration needed | J13: 4 — APIs mostly ready
B14: F3 | C14: Technical Feasibility | D14: 0.25 | E14: 3 — Needs new tools/skills | F14: 5 — Prototype in 1–2 wks | G14: 3 — Needs new tools/skills | H14: 3 — Needs new tools/skills | I14: 2 — Major custom work | J14: 2 — Major custom work
B15: F4 | C15: Autonomy Fit | D15: 0.15 | E15: 5 — Low-risk full autonomy | F15: 5 — Low-risk full autonomy | G15: 5 — Low-risk full autonomy | H15: 5 — Low-risk full autonomy | I15: 2 — Hard to govern | J15: 5 — Low-risk full autonomy
B16: F5 | C16: Time to Value | D16: 0.15 | E16: 3 — 1–3 months to value | F16: 4 — Weeks to first value | G16: 3 — 1–3 months to value | H16: 3 — 1–3 months to value | I16: 3 — 1–3 months to value | J16: 3 — 1–3 months to value
C17: Weighted Feasibility Score | E17: =IF((IF(E12="",0,1)+IF(E13="",0,1)+IF(E14="",0,1)+IF(E15="",0,1)+IF(E16="",0,1))=0,"",(IF(E12="",0,VALUE(LEFT(E12,1))*$D$12)+IF(E13="",0,VALUE(LEFT(E13,1))*$D$13)+IF(E14="",0,VALUE(LEFT(E14,1))*$D$14)+IF(E15="",0,VALUE(LEFT(E15,1))*$D$15)+IF(E16="",0,VALUE(LEFT(E16,1))*$D$16))/(IF(E12="",0,$D$12)+IF(E13="",0,$D$13)+IF(E14="",0,$D$14)+IF(E15="",0,$D$15)+IF(E16="",0,$D$16))) -> 3.25 | F17: =IF((IF(F12="",0,1)+IF(F13="",0,1)+IF(F14="",0,1)+IF(F15="",0,1)+IF(F16="",0,1))=0,"",(IF(F12="",0,VALUE(LEFT(F12,1))*$D$12)+IF(F13="",0,VALUE(LEFT(F13,1))*$D$13)+IF(F14="",0,VALUE(LEFT(F14,1))*$D$14)+IF(F15="",0,VALUE(LEFT(F15,1))*$D$15)+IF(F16="",0,VALUE(LEFT(F16,1))*$D$16))/(IF(F12="",0,$D$12)+IF(F13="",0,$D$13)+IF(F14="",0,$D$14)+IF(F15="",0,$D$15)+IF(F16="",0,$D$16))) -> 4.6 | G17: =IF((IF(G12="",0,1)+IF(G13="",0,1)+IF(G14="",0,1)+IF(G15="",0,1)+IF(G16="",0,1))=0,"",(IF(G12="",0,VALUE(LEFT(G12,1))*$D$12)+IF(G13="",0,VALUE(LEFT(G13,1))*$D$13)+IF(G14="",0,VALUE(LEFT(G14,1))*$D$14)+IF(G15="",0,VALUE(LEFT(G15,1))*$D$15)+IF(G16="",0,VALUE(LEFT(G16,1))*$D$16))/(IF(G12="",0,$D$12)+IF(G13="",0,$D$13)+IF(G14="",0,$D$14)+IF(G15="",0,$D$15)+IF(G16="",0,$D$16))) -> 3.3 | H17: =IF((IF(H12="",0,1)+IF(H13="",0,1)+IF(H14="",0,1)+IF(H15="",0,1)+IF(H16="",0,1))=0,"",(IF(H12="",0,VALUE(LEFT(H12,1))*$D$12)+IF(H13="",0,VALUE(LEFT(H13,1))*$D$13)+IF(H14="",0,VALUE(LEFT(H14,1))*$D$14)+IF(H15="",0,VALUE(LEFT(H15,1))*$D$15)+IF(H16="",0,VALUE(LEFT(H16,1))*$D$16))/(IF(H12="",0,$D$12)+IF(H13="",0,$D$13)+IF(H14="",0,$D$14)+IF(H15="",0,$D$15)+IF(H16="",0,$D$16))) -> 3.6 | I17: =IF((IF(I12="",0,1)+IF(I13="",0,1)+IF(I14="",0,1)+IF(I15="",0,1)+IF(I16="",0,1))=0,"",(IF(I12="",0,VALUE(LEFT(I12,1))*$D$12)+IF(I13="",0,VALUE(LEFT(I13,1))*$D$13)+IF(I14="",0,VALUE(LEFT(I14,1))*$D$14)+IF(I15="",0,VALUE(LEFT(I15,1))*$D$15)+IF(I16="",0,VALUE(LEFT(I16,1))*$D$16))/(IF(I12="",0,$D$12)+IF(I13="",0,$D$13)+IF(I14="",0,$D$14)+IF(I15="",0,$D$15)+IF(I16="",0,$D$16))) -> 3.1 | J17: =IF((IF(J12="",0,1)+IF(J13="",0,1)+IF(J14="",0,1)+IF(J15="",0,1)+IF(J16="",0,1))=0,"",(IF(J12="",0,VALUE(LEFT(J12,1))*$D$12)+IF(J13="",0,VALUE(LEFT(J13,1))*$D$13)+IF(J14="",0,VALUE(LEFT(J14,1))*$D$14)+IF(J15="",0,VALUE(LEFT(J15,1))*$D$15)+IF(J16="",0,VALUE(LEFT(J16,1))*$D$16))/(IF(J12="",0,$D$12)+IF(J13="",0,$D$13)+IF(J14="",0,$D$14)+IF(J15="",0,$D$15)+IF(J16="",0,$D$16))) -> 3.75 | K17: =IF((IF(K12="",0,1)+IF(K13="",0,1)+IF(K14="",0,1)+IF(K15="",0,1)+IF(K16="",0,1))=0,"",(IF(K12="",0,VALUE(LEFT(K12,1))*$D$12)+IF(K13="",0,VALUE(LEFT(K13,1))*$D$13)+IF(K14="",0,VALUE(LEFT(K14,1))*$D$14)+IF(K15="",0,VALUE(LEFT(K15,1))*$D$15)+IF(K16="",0,VALUE(LEFT(K16,1))*$D$16))/(IF(K12="",0,$D$12)+IF(K13="",0,$D$13)+IF(K14="",0,$D$14)+IF(K15="",0,$D$15)+IF(K16="",0,$D$16))) | L17: =IF((IF(L12="",0,1)+IF(L13="",0,1)+IF(L14="",0,1)+IF(L15="",0,1)+IF(L16="",0,1))=0,"",(IF(L12="",0,VALUE(LEFT(L12,1))*$D$12)+IF(L13="",0,VALUE(LEFT(L13,1))*$D$13)+IF(L14="",0,VALUE(LEFT(L14,1))*$D$14)+IF(L15="",0,VALUE(LEFT(L15,1))*$D$15)+IF(L16="",0,VALUE(LEFT(L16,1))*$D$16))/(IF(L12="",0,$D$12)+IF(L13="",0,$D$13)+IF(L14="",0,$D$14)+IF(L15="",0,$D$15)+IF(L16="",0,$D$16))) | ... N17: =IF((IF(N12="",0,1)+IF(N13="",0,1)+IF(N14="",0,1)+IF(N15="",0,1)+IF(N16="",0,1))=0,"",(IF(N12="",0,VALUE(LEFT(N12,1))*$D$12)+IF(N13="",0,VALUE(LEFT(N13,1))*$D$13)+IF(N14="",0,VALUE(LEFT(N14,1))*$D$14)+IF(N15="",0,VALUE(LEFT(N15,1))*$D$15)+IF(N16="",0,VALUE(LEFT(N16,1))*$D$16))/(IF(N12="",0,$D$12)+IF(N13="",0,$D$13)+IF(N14="",0,$D$14)+IF(N15="",0,$D$15)+IF(N16="",0,$D$16)))
C18: → Interpretation: 4.0+ = highly feasible, 3.0–3.9 = feasible with effort, 2.0–2.9 = significant barriers, below 2.0 = not feasible today
B20: IMPACT — Is it worth it?
B21: I1 | C21: Time Saved | D21: 0.25 | E21: 2 — 2–5 hrs/wk | F21: 1 — Under 2 hrs/wk | G21: 2 — 2–5 hrs/wk | H21: 2 — 2–5 hrs/wk | I21: 2 — 2–5 hrs/wk | J21: 3 — 5–15 hrs/wk
B22: I2 | C22: Cost Reduction | D22: 0.2 | E22: 1 — Negligible | F22: 1 — Negligible | G22: 1 — Negligible | H22: 1 — Negligible | I22: 1 — Negligible | J22: 1 — Negligible
B23: I3 | C23: Error Reduction | D23: 0.2 | E23: 3 — Regular moderate | F23: 1 — Rare & minor | G23: 3 — Regular moderate | H23: 3 — Regular moderate | I23: 3 — Regular moderate | J23: 3 — Regular moderate
B24: I4 | C24: Revenue Potential | D24: 0.15 | E24: 3 — Faster cycles | F24: 1 — No revenue link | G24: 4 — Accelerates revenue | H24: 4 — Accelerates revenue | I24: 3 — Faster cycles | J24: 4 — Accelerates revenue
B25: I5 | C25: Scale Leverage | D25: 0.2 | E25: 1 — One person | F25: 1 — One person | G25: 1 — One person | H25: 1 — One person | I25: 1 — One person | J25: 1 — One person
C26: Weighted Impact Score | E26: =IF((IF(E21="",0,1)+IF(E22="",0,1)+IF(E23="",0,1)+IF(E24="",0,1)+IF(E25="",0,1))=0,"",(IF(E21="",0,VALUE(LEFT(E21,1))*$D$21)+IF(E22="",0,VALUE(LEFT(E22,1))*$D$22)+IF(E23="",0,VALUE(LEFT(E23,1))*$D$23)+IF(E24="",0,VALUE(LEFT(E24,1))*$D$24)+IF(E25="",0,VALUE(LEFT(E25,1))*$D$25))/(IF(E21="",0,$D$21)+IF(E22="",0,$D$22)+IF(E23="",0,$D$23)+IF(E24="",0,$D$24)+IF(E25="",0,$D$25))) -> 1.95 | F26: =IF((IF(F21="",0,1)+IF(F22="",0,1)+IF(F23="",0,1)+IF(F24="",0,1)+IF(F25="",0,1))=0,"",(IF(F21="",0,VALUE(LEFT(F21,1))*$D$21)+IF(F22="",0,VALUE(LEFT(F22,1))*$D$22)+IF(F23="",0,VALUE(LEFT(F23,1))*$D$23)+IF(F24="",0,VALUE(LEFT(F24,1))*$D$24)+IF(F25="",0,VALUE(LEFT(F25,1))*$D$25))/(IF(F21="",0,$D$21)+IF(F22="",0,$D$22)+IF(F23="",0,$D$23)+IF(F24="",0,$D$24)+IF(F25="",0,$D$25))) -> 1 | G26: =IF((IF(G21="",0,1)+IF(G22="",0,1)+IF(G23="",0,1)+IF(G24="",0,1)+IF(G25="",0,1))=0,"",(IF(G21="",0,VALUE(LEFT(G21,1))*$D$21)+IF(G22="",0,VALUE(LEFT(G22,1))*$D$22)+IF(G23="",0,VALUE(LEFT(G23,1))*$D$23)+IF(G24="",0,VALUE(LEFT(G24,1))*$D$24)+IF(G25="",0,VALUE(LEFT(G25,1))*$D$25))/(IF(G21="",0,$D$21)+IF(G22="",0,$D$22)+IF(G23="",0,$D$23)+IF(G24="",0,$D$24)+IF(G25="",0,$D$25))) -> 2.1 | H26: =IF((IF(H21="",0,1)+IF(H22="",0,1)+IF(H23="",0,1)+IF(H24="",0,1)+IF(H25="",0,1))=0,"",(IF(H21="",0,VALUE(LEFT(H21,1))*$D$21)+IF(H22="",0,VALUE(LEFT(H22,1))*$D$22)+IF(H23="",0,VALUE(LEFT(H23,1))*$D$23)+IF(H24="",0,VALUE(LEFT(H24,1))*$D$24)+IF(H25="",0,VALUE(LEFT(H25,1))*$D$25))/(IF(H21="",0,$D$21)+IF(H22="",0,$D$22)+IF(H23="",0,$D$23)+IF(H24="",0,$D$24)+IF(H25="",0,$D$25))) -> 2.1 | I26: =IF((IF(I21="",0,1)+IF(I22="",0,1)+IF(I23="",0,1)+IF(I24="",0,1)+IF(I25="",0,1))=0,"",(IF(I21="",0,VALUE(LEFT(I21,1))*$D$21)+IF(I22="",0,VALUE(LEFT(I22,1))*$D$22)+IF(I23="",0,VALUE(LEFT(I23,1))*$D$23)+IF(I24="",0,VALUE(LEFT(I24,1))*$D$24)+IF(I25="",0,VALUE(LEFT(I25,1))*$D$25))/(IF(I21="",0,$D$21)+IF(I22="",0,$D$22)+IF(I23="",0,$D$23)+IF(I24="",0,$D$24)+IF(I25="",0,$D$25))) -> 1.95 | J26: =IF((IF(J21="",0,1)+IF(J22="",0,1)+IF(J23="",0,1)+IF(J24="",0,1)+IF(J25="",0,1))=0,"",(IF(J21="",0,VALUE(LEFT(J21,1))*$D$21)+IF(J22="",0,VALUE(LEFT(J22,1))*$D$22)+IF(J23="",0,VALUE(LEFT(J23,1))*$D$23)+IF(J24="",0,VALUE(LEFT(J24,1))*$D$24)+IF(J25="",0,VALUE(LEFT(J25,1))*$D$25))/(IF(J21="",0,$D$21)+IF(J22="",0,$D$22)+IF(J23="",0,$D$23)+IF(J24="",0,$D$24)+IF(J25="",0,$D$25))) -> 2.35 | K26: =IF((IF(K21="",0,1)+IF(K22="",0,1)+IF(K23="",0,1)+IF(K24="",0,1)+IF(K25="",0,1))=0,"",(IF(K21="",0,VALUE(LEFT(K21,1))*$D$21)+IF(K22="",0,VALUE(LEFT(K22,1))*$D$22)+IF(K23="",0,VALUE(LEFT(K23,1))*$D$23)+IF(K24="",0,VALUE(LEFT(K24,1))*$D$24)+IF(K25="",0,VALUE(LEFT(K25,1))*$D$25))/(IF(K21="",0,$D$21)+IF(K22="",0,$D$22)+IF(K23="",0,$D$23)+IF(K24="",0,$D$24)+IF(K25="",0,$D$25))) | L26: =IF((IF(L21="",0,1)+IF(L22="",0,1)+IF(L23="",0,1)+IF(L24="",0,1)+IF(L25="",0,1))=0,"",(IF(L21="",0,VALUE(LEFT(L21,1))*$D$21)+IF(L22="",0,VALUE(LEFT(L22,1))*$D$22)+IF(L23="",0,VALUE(LEFT(L23,1))*$D$23)+IF(L24="",0,VALUE(LEFT(L24,1))*$D$24)+IF(L25="",0,VALUE(LEFT(L25,1))*$D$25))/(IF(L21="",0,$D$21)+IF(L22="",0,$D$22)+IF(L23="",0,$D$23)+IF(L24="",0,$D$24)+IF(L25="",0,$D$25))) | ... N26: =IF((IF(N21="",0,1)+IF(N22="",0,1)+IF(N23="",0,1)+IF(N24="",0,1)+IF(N25="",0,1))=0,"",(IF(N21="",0,VALUE(LEFT(N21,1))*$D$21)+IF(N22="",0,VALUE(LEFT(N22,1))*$D$22)+IF(N23="",0,VALUE(LEFT(N23,1))*$D$23)+IF(N24="",0,VALUE(LEFT(N24,1))*$D$24)+IF(N25="",0,VALUE(LEFT(N25,1))*$D$25))/(IF(N21="",0,$D$21)+IF(N22="",0,$D$22)+IF(N23="",0,$D$23)+IF(N24="",0,$D$24)+IF(N25="",0,$D$25)))
C27: → Interpretation: 4.0+ = transformative impact, 3.0–3.9 = meaningful impact, 2.0–2.9 = modest impact, below 2.0 = minimal value
B29: COMPOSITE SCORE & RECOMMENDATION
C30: Composite (50% Feasibility + 50% Impact) | E30: =IF(AND(E17="",E26=""),"",IF(E17="",E26,IF(E26="",E17,E17*0.5+E26*0.5))) -> 2.6 | F30: =IF(AND(F17="",F26=""),"",IF(F17="",F26,IF(F26="",F17,F17*0.5+F26*0.5))) -> 2.8 | G30: =IF(AND(G17="",G26=""),"",IF(G17="",G26,IF(G26="",G17,G17*0.5+G26*0.5))) -> 2.7 | H30: =IF(AND(H17="",H26=""),"",IF(H17="",H26,IF(H26="",H17,H17*0.5+H26*0.5))) -> 2.85 | I30: =IF(AND(I17="",I26=""),"",IF(I17="",I26,IF(I26="",I17,I17*0.5+I26*0.5))) -> 2.525 | J30: =IF(AND(J17="",J26=""),"",IF(J17="",J26,IF(J26="",J17,J17*0.5+J26*0.5))) -> 3.05 | K30: =IF(AND(K17="",K26=""),"",IF(K17="",K26,IF(K26="",K17,K17*0.5+K26*0.5))) | L30: =IF(AND(L17="",L26=""),"",IF(L17="",L26,IF(L26="",L17,L17*0.5+L26*0.5))) | ... N30: =IF(AND(N17="",N26=""),"",IF(N17="",N26,IF(N26="",N17,N17*0.5+N26*0.5)))
C31: Rank | E31: =IF(E30="","",RANK(E30,$E$30:$N$30,0)) -> 5 | F31: =IF(F30="","",RANK(F30,$E$30:$N$30,0)) -> 3 | G31: =IF(G30="","",RANK(G30,$E$30:$N$30,0)) -> 4 | H31: =IF(H30="","",RANK(H30,$E$30:$N$30,0)) -> 2 | I31: =IF(I30="","",RANK(I30,$E$30:$N$30,0)) -> 6 | J31: =IF(J30="","",RANK(J30,$E$30:$N$30,0)) -> 1 | K31: =IF(K30="","",RANK(K30,$E$30:$N$30,0)) | L31: =IF(L30="","",RANK(L30,$E$30:$N$30,0)) | ... N31: =IF(N30="","",RANK(N30,$E$30:$N$30,0))
C32: Recommendation | E32: =IF(E30="","",IF(E30>=4,"✅ Pursue",IF(E30>=3,"🔍 Investigate",IF(E30>=2,"⏸️ Park","❌ Drop")))) -> ⏸️ Park | F32: =IF(F30="","",IF(F30>=4,"✅ Pursue",IF(F30>=3,"🔍 Investigate",IF(F30>=2,"⏸️ Park","❌ Drop")))) -> ⏸️ Park | G32: =IF(G30="","",IF(G30>=4,"✅ Pursue",IF(G30>=3,"🔍 Investigate",IF(G30>=2,"⏸️ Park","❌ Drop")))) -> ⏸️ Park | H32: =IF(H30="","",IF(H30>=4,"✅ Pursue",IF(H30>=3,"🔍 Investigate",IF(H30>=2,"⏸️ Park","❌ Drop")))) -> ⏸️ Park | I32: =IF(I30="","",IF(I30>=4,"✅ Pursue",IF(I30>=3,"🔍 Investigate",IF(I30>=2,"⏸️ Park","❌ Drop")))) -> ⏸️ Park | J32: =IF(J30="","",IF(J30>=4,"✅ Pursue",IF(J30>=3,"🔍 Investigate",IF(J30>=2,"⏸️ Park","❌ Drop")))) -> 🔍 Investigate | K32: =IF(K30="","",IF(K30>=4,"✅ Pursue",IF(K30>=3,"🔍 Investigate",IF(K30>=2,"⏸️ Park","❌ Drop")))) | L32: =IF(L30="","",IF(L30>=4,"✅ Pursue",IF(L30>=3,"🔍 Investigate",IF(L30>=2,"⏸️ Park","❌ Drop")))) | ... N32: =IF(N30="","",IF(N30>=4,"✅ Pursue",IF(N30>=3,"🔍 Investigate",IF(N30>=2,"⏸️ Park","❌ Drop"))))
C34: → How to read the recommendations: ✅ Pursue = strong candidate, proceed to Risk Assessment. 🔍 Investigate = promising but has gaps — identify which dimension is pulling the score down and decide if it's fixable. ⏸️ Park = not ready — revisit if conditions change. ❌ Drop = the math doesn't work right now. Take your top 3–5 (those scoring ≥ 3.0) to the Risk Assessment tab.

Sheet Risk Assessment
B2: Step 3: Risk Assessment
B3: For your top candidates (composite score ≥ 3.0), assess the 7 risk dimensions below.
B5: Risk scoring works differently from feasibility and impact: here, lower is better. Score 1 = minimal risk, 5 = severe risk. The first 4 dimensions (R1–R4) are standard enterprise risks. The last 3 (R5–R7) are specific to AI agent systems — these are the failure modes that traditional project risk assessments miss, including hallucination, integration fragility, and drift. The workbook will map your average risk score to an autonomy recommendation based on the framework in The Agentic Enterprise Strategy.
B6: Risk Scale: 1 = Minimal risk | 2 = Low risk | 3 = Moderate risk | 4 = High risk | 5 = Severe risk
B8: # | C8: Risk Dimension | D8: What to Consider | E8: #1 Ranked | F8: #2 Ranked | G8: #3 Ranked | H8: #4 Ranked | I8: #5 Ranked
C9: Use case name: | E9: =IFERROR(INDEX(Scoring!$E$9:$N$9,1,MATCH(1,Scoring!$E$31:$N$31,0)),"") -> Travel Agent | F9: =IFERROR(INDEX(Scoring!$E$9:$N$9,1,MATCH(2,Scoring!$E$31:$N$31,0)),"") -> Real Estate Franchisee | G9: =IFERROR(INDEX(Scoring!$E$9:$N$9,1,MATCH(3,Scoring!$E$31:$N$31,0)),"") -> News Letter - Daily Quotes | H9: =IFERROR(INDEX(Scoring!$E$9:$N$9,1,MATCH(4,Scoring!$E$31:$N$31,0)),"") -> Real Estate Searcher | I9: =IFERROR(INDEX(Scoring!$E$9:$N$9,1,MATCH(5,Scoring!$E$31:$N$31,0)),"") -> Stock Market Guide
B11: R1 | C11: Failure Consequence | D11: What's the worst-case harm if the agent makes an unchecked wrong decision? Financial loss, legal violations, safety issues, customer trust damage. | E11: 3 — Moderate cost/impact | F11: 4 — Significant damage | G11: 1 — Easily corrected | H11: 4 — Significant damage | I11: 4 — Significant damage
B12: R2 | C12: Data Sensitivity | D12: Does this involve PII, financial records, health data, or trade secrets? What's the exposure if data leaks or is mishandled? | E12: 3 — Some personal data | F12: 3 — Some personal data | G12: 1 — Public data only | H12: 3 — Some personal data | I12: 3 — Some personal data
B13: R3 | C13: Regulatory Exposure | D13: Subject to HIPAA, GDPR, SOC 2, financial regulations, industry-specific compliance? Regulated = governance-by-design. | E13: 1 — No regulation | F13: 2 — Internal policies | G13: 1 — No regulation | H13: 2 — Internal policies | I13: 3 — SOC 2 / ISO
B14: R4 | C14: Organizational Readiness | D14: Does the team have the skills, infrastructure, and cultural willingness? Even a great agent fails if the org isn't ready. | E14: 2 — Some skill gaps | F14: 2 — Some skill gaps | G14: 2 — Some skill gaps | H14: 2 — Some skill gaps | I14: 2 — Some skill gaps
B15: R5 | C15: Hallucination Risk | D15: How critical is factual accuracy? What happens when the agent is confidently wrong? Tasks with verifiable outputs (code, math) are safer than open-ended content generation. | E15: 2 — Spot-checkable | F15: 3 — Some hard to verify | G15: 1 — Verifiable outputs | H15: 3 — Some hard to verify | I15: 3 — Some hard to verify
B16: R6 | C16: MCP & Integration Fragility | D16: How many external systems must the agent connect to? Each MCP integration is a failure point. Brittle APIs, auth changes, and rate limits compound. | E16: 4 — 5+ mixed quality | F16: 5 — Many brittle APIs | G16: 1 — Single stable API | H16: 5 — Many brittle APIs | I16: 4 — 5+ mixed quality
B17: R7 | C17: Context & Skill Drift | D17: Will the agent's context, skills, and memory stay accurate over time? Business processes change, schemas evolve, APIs update. Score 5 if environment changes frequently. | E17: 2 — Quarterly predictable | F17: 4 — Frequent hard to track | G17: 1 — Stable rarely changes | H17: 2 — Quarterly predictable | I17: 4 — Frequent hard to track
C19: Average Risk Score | D19: Lower is better. | E19: =IF((IF(E11="",0,1)+IF(E12="",0,1)+IF(E13="",0,1)+IF(E14="",0,1)+IF(E15="",0,1)+IF(E16="",0,1)+IF(E17="",0,1))=0,"",(IF(E11="",0,VALUE(LEFT(E11,1)))+IF(E12="",0,VALUE(LEFT(E12,1)))+IF(E13="",0,VALUE(LEFT(E13,1)))+IF(E14="",0,VALUE(LEFT(E14,1)))+IF(E15="",0,VALUE(LEFT(E15,1)))+IF(E16="",0,VALUE(LEFT(E16,1)))+IF(E17="",0,VALUE(LEFT(E17,1))))/(IF(E11="",0,1)+IF(E12="",0,1)+IF(E13="",0,1)+IF(E14="",0,1)+IF(E15="",0,1)+IF(E16="",0,1)+IF(E17="",0,1))) -> 2.4285714 | F19: =IF((IF(F11="",0,1)+IF(F12="",0,1)+IF(F13="",0,1)+IF(F14="",0,1)+IF(F15="",0,1)+IF(F16="",0,1)+IF(F17="",0,1))=0,"",(IF(F11="",0,VALUE(LEFT(F11,1)))+IF(F12="",0,VALUE(LEFT(F12,1)))+IF(F13="",0,VALUE(LEFT(F13,1)))+IF(F14="",0,VALUE(LEFT(F14,1)))+IF(F15="",0,VALUE(LEFT(F15,1)))+IF(F16="",0,VALUE(LEFT(F16,1)))+IF(F17="",0,VALUE(LEFT(F17,1))))/(IF(F11="",0,1)+IF(F12="",0,1)+IF(F13="",0,1)+IF(F14="",0,1)+IF(F15="",0,1)+IF(F16="",0,1)+IF(F17="",0,1))) -> 3.2857143 | G19: =IF((IF(G11="",0,1)+IF(G12="",0,1)+IF(G13="",0,1)+IF(G14="",0,1)+IF(G15="",0,1)+IF(G16="",0,1)+IF(G17="",0,1))=0,"",(IF(G11="",0,VALUE(LEFT(G11,1)))+IF(G12="",0,VALUE(LEFT(G12,1)))+IF(G13="",0,VALUE(LEFT(G13,1)))+IF(G14="",0,VALUE(LEFT(G14,1)))+IF(G15="",0,VALUE(LEFT(G15,1)))+IF(G16="",0,VALUE(LEFT(G16,1)))+IF(G17="",0,VALUE(LEFT(G17,1))))/(IF(G11="",0,1)+IF(G12="",0,1)+IF(G13="",0,1)+IF(G14="",0,1)+IF(G15="",0,1)+IF(G16="",0,1)+IF(G17="",0,1))) -> 1.1428571 | H19: =IF((IF(H11="",0,1)+IF(H12="",0,1)+IF(H13="",0,1)+IF(H14="",0,1)+IF(H15="",0,1)+IF(H16="",0,1)+IF(H17="",0,1))=0,"",(IF(H11="",0,VALUE(LEFT(H11,1)))+IF(H12="",0,VALUE(LEFT(H12,1)))+IF(H13="",0,VALUE(LEFT(H13,1)))+IF(H14="",0,VALUE(LEFT(H14,1)))+IF(H15="",0,VALUE(LEFT(H15,1)))+IF(H16="",0,VALUE(LEFT(H16,1)))+IF(H17="",0,VALUE(LEFT(H17,1))))/(IF(H11="",0,1)+IF(H12="",0,1)+IF(H13="",0,1)+IF(H14="",0,1)+IF(H15="",0,1)+IF(H16="",0,1)+IF(H17="",0,1))) -> 3 | I19: =IF((IF(I11="",0,1)+IF(I12="",0,1)+IF(I13="",0,1)+IF(I14="",0,1)+IF(I15="",0,1)+IF(I16="",0,1)+IF(I17="",0,1))=0,"",(IF(I11="",0,VALUE(LEFT(I11,1)))+IF(I12="",0,VALUE(LEFT(I12,1)))+IF(I13="",0,VALUE(LEFT(I13,1)))+IF(I14="",0,VALUE(LEFT(I14,1)))+IF(I15="",0,VALUE(LEFT(I15,1)))+IF(I16="",0,VALUE(LEFT(I16,1)))+IF(I17="",0,VALUE(LEFT(I17,1))))/(IF(I11="",0,1)+IF(I12="",0,1)+IF(I13="",0,1)+IF(I14="",0,1)+IF(I15="",0,1)+IF(I16="",0,1)+IF(I17="",0,1))) -> 3.2857143
C20: Risk Level | E20: =IF(E19="","",IF(E19<=2,"🟢 Low",IF(E19<=3.5,"🟡 Medium","🔴 High"))) -> 🟡 Medium | F20: =IF(F19="","",IF(F19<=2,"🟢 Low",IF(F19<=3.5,"🟡 Medium","🔴 High"))) -> 🟡 Medium | G20: =IF(G19="","",IF(G19<=2,"🟢 Low",IF(G19<=3.5,"🟡 Medium","🔴 High"))) -> 🟢 Low | H20: =IF(H19="","",IF(H19<=2,"🟢 Low",IF(H19<=3.5,"🟡 Medium","🔴 High"))) -> 🟡 Medium | I20: =IF(I19="","",IF(I19<=2,"🟢 Low",IF(I19<=3.5,"🟡 Medium","🔴 High"))) -> 🟡 Medium
C21: Autonomy Recommendation | E21: =IF(E19="","",IF(E19<=2,"Full Autonomy",IF(E19<=3.5,"Supervised Execution","Human-Required"))) -> Supervised Execution | F21: =IF(F19="","",IF(F19<=2,"Full Autonomy",IF(F19<=3.5,"Supervised Execution","Human-Required"))) -> Supervised Execution | G21: =IF(G19="","",IF(G19<=2,"Full Autonomy",IF(G19<=3.5,"Supervised Execution","Human-Required"))) -> Full Autonomy | H21: =IF(H19="","",IF(H19<=2,"Full Autonomy",IF(H19<=3.5,"Supervised Execution","Human-Required"))) -> Supervised Execution | I21: =IF(I19="","",IF(I19<=2,"Full Autonomy",IF(I19<=3.5,"Supervised Execution","Human-Required"))) -> Supervised Execution
B23: → How to interpret: 🟢 Low risk (avg ≤ 2.0) = Full Autonomy — agent can operate independently. 🟡 Medium risk (2.1–3.5) = Supervised Execution — agent proposes, human approves key actions. 🔴 High risk (> 3.5) = Human-Required — agent assists, human decides. If R5 (Hallucination) or R6 (Integration Fragility) alone scores 5, consider that a flag regardless of the average. A single catastrophic dimension can outweigh a safe average.
B26: Autonomy Calibration — From The Agentic Enterprise Strategy, Chapter 3
C28: 🟢 Full Autonomy | D28: Avg risk ≤ 2.0 | E28: Agent operates independently. Low-consequence tasks: content drafts, research summaries, inbox triage, data gathering.
C29: 🟡 Supervised Execution | D29: Avg risk 2.1–3.5 | E29: Agent proposes actions, human approves before execution. Medium-stakes: small transactions, email sends, schedule changes, report generation.
C30: 🔴 Human-Required | D30: Avg risk > 3.5 | E30: Agent assists with analysis and drafts, but human makes the decision. High-stakes: financial, legal, compliance, customer-facing decisions with real consequences.

Sheet Prioritization Matrix
B2: Step 4: Prioritization Matrix
B3: This tab is fully auto-generated from your Scoring and Risk Assessment tabs. You don't need to enter anything here.
B5: The table below pulls every use case's scores, ranks them by composite, maps risk levels from the Risk Assessment tab, and provides a final recommendation. Use this as your decision summary — the artifact you bring to a planning meeting or share with stakeholders. The quadrant guide helps you interpret where each candidate falls.
B6: Quadrant Guide — How to Interpret the Scores
B8: 🎯 Build This First | D8: Feasibility ≥ 3.5 AND Impact ≥ 3.5 | F8: Your strongest candidates. High confidence you can build it AND it's worth building. Proceed to Selection Brief.
B9: 💡 High Impact but Hard | D9: Feasibility < 3.5 AND Impact ≥ 3.5 | F9: The payoff is real but there are barriers. Identify which feasibility dimension is lowest — is it fixable with more time, data, or tools?
B10: ⚡ Quick Win | D10: Feasibility ≥ 3.5 AND Impact < 3.5 | F10: Easy to build but limited strategic value. Good for learning, building team confidence, or demonstrating agent capabilities. Not your lead initiative.
B11: ⏸️ Deprioritize | D11: Feasibility < 3.5 AND Impact < 3.5 | F11: Not ready. Park these and revisit when conditions change — better tools, more data, different business priorities.
B14: Ranked Use Cases
B15: All values below are auto-calculated. The Risk Level column pulls from the Risk Assessment tab by matching candidate names. Candidates are listed in the order they were entered — check the Rank column to see the actual priority order.
B17: Rank | C17: Use Case Name | D17: Feasibility | E17: Impact | F17: Composite | G17: Risk Level | H17: Autonomy | I17: Risk-Adjusted Recommendation | J17: Risk-Adjusted Score | K17: Adjusted Rank
B18: =IF(Scoring!E30<>"",Scoring!E31,"") -> 5 | C18: =IF(Scoring!E9<>"—",Scoring!E9,"") -> Stock Market Guide | D18: =IF(Scoring!E17<>"",Scoring!E17,"") -> 3.25 | E18: =IF(Scoring!E26<>"",Scoring!E26,"") -> 1.95 | F18: =IF(Scoring!E30<>"",Scoring!E30,"") -> 2.6 | G18: =IFERROR(INDEX('Risk Assessment'!$E$20:$I$20,1,MATCH(Scoring!E9,'Risk Assessment'!$E$9:$I$9,0)),"—") -> 🟡 Medium | H18: =IFERROR(INDEX('Risk Assessment'!$E$21:$I$21,1,MATCH(Scoring!E9,'Risk Assessment'!$E$9:$I$9,0)),"—") -> Supervised Execution | I18: =IF(F18="","",IF(F18>=4,IF(OR(G18="—",G18=""),"✅ Pursue",IF(ISNUMBER(SEARCH("Low",G18)),"✅ Pursue",IF(ISNUMBER(SEARCH("Medium",G18)),"✅ Pursue (Supervised)","⚠️ Investigate — mitigate risk"))),IF(F18>=3,IF(OR(G18="—",G18=""),"🔍 Investigate",IF(ISNUMBER(SEARCH("High",G18)),"⏸️ Park — risk too high","🔍 Investigate")),IF(F18>=2,"⏸️ Park","❌ Drop")))) -> ⏸️ Park | J18: =IF(F18="","",IF(OR(G18="—",G18=""),F18,IF(ISNUMBER(SEARCH("Low",G18)),F18*1,IF(ISNUMBER(SEARCH("Medium",G18)),F18*0.85,F18*0.7)))) -> 2.21 | K18: =IF(J18="","",RANK(J18,$J$18:$J$27,0)) -> 6
B19: =IF(Scoring!F30<>"",Scoring!F31,"") -> 3 | C19: =IF(Scoring!F9<>"—",Scoring!F9,"") -> News Letter - Daily Quotes | D19: =IF(Scoring!F17<>"",Scoring!F17,"") -> 4.6 | E19: =IF(Scoring!F26<>"",Scoring!F26,"") -> 1 | F19: =IF(Scoring!F30<>"",Scoring!F30,"") -> 2.8 | G19: =IFERROR(INDEX('Risk Assessment'!$E$20:$I$20,1,MATCH(Scoring!F9,'Risk Assessment'!$E$9:$I$9,0)),"—") -> 🟢 Low | H19: =IFERROR(INDEX('Risk Assessment'!$E$21:$I$21,1,MATCH(Scoring!F9,'Risk Assessment'!$E$9:$I$9,0)),"—") -> Full Autonomy | I19: =IF(F19="","",IF(F19>=4,IF(OR(G19="—",G19=""),"✅ Pursue",IF(ISNUMBER(SEARCH("Low",G19)),"✅ Pursue",IF(ISNUMBER(SEARCH("Medium",G19)),"✅ Pursue (Supervised)","⚠️ Investigate — mitigate risk"))),IF(F19>=3,IF(OR(G19="—",G19=""),"🔍 Investigate",IF(ISNUMBER(SEARCH("High",G19)),"⏸️ Park — risk too high","🔍 Investigate")),IF(F19>=2,"⏸️ Park","❌ Drop")))) -> ⏸️ Park | J19: =IF(F19="","",IF(OR(G19="—",G19=""),F19,IF(ISNUMBER(SEARCH("Low",G19)),F19*1,IF(ISNUMBER(SEARCH("Medium",G19)),F19*0.85,F19*0.7)))) -> 2.8 | K19: =IF(J19="","",RANK(J19,$J$18:$J$27,0)) -> 1
B20: =IF(Scoring!G30<>"",Scoring!G31,"") -> 4 | C20: =IF(Scoring!G9<>"—",Scoring!G9,"") -> Real Estate Searcher | D20: =IF(Scoring!G17<>"",Scoring!G17,"") -> 3.3 | E20: =IF(Scoring!G26<>"",Scoring!G26,"") -> 2.1 | F20: =IF(Scoring!G30<>"",Scoring!G30,"") -> 2.7 | G20: =IFERROR(INDEX('Risk Assessment'!$E$20:$I$20,1,MATCH(Scoring!G9,'Risk Assessment'!$E$9:$I$9,0)),"—") -> 🟡 Medium | H20: =IFERROR(INDEX('Risk Assessment'!$E$21:$I$21,1,MATCH(Scoring!G9,'Risk Assessment'!$E$9:$I$9,0)),"—") -> Supervised Execution | I20: =IF(F20="","",IF(F20>=4,IF(OR(G20="—",G20=""),"✅ Pursue",IF(ISNUMBER(SEARCH("Low",G20)),"✅ Pursue",IF(ISNUMBER(SEARCH("Medium",G20)),"✅ Pursue (Supervised)","⚠️ Investigate — mitigate risk"))),IF(F20>=3,IF(OR(G20="—",G20=""),"🔍 Investigate",IF(ISNUMBER(SEARCH("High",G20)),"⏸️ Park — risk too high","🔍 Investigate")),IF(F20>=2,"⏸️ Park","❌ Drop")))) -> ⏸️ Park | J20: =IF(F20="","",IF(OR(G20="—",G20=""),F20,IF(ISNUMBER(SEARCH("Low",G20)),F20*1,IF(ISNUMBER(SEARCH("Medium",G20)),F20*0.85,F20*0.7)))) -> 2.295 | K20: =IF(J20="","",RANK(J20,$J$18:$J$27,0)) -> 5
B21: =IF(Scoring!H30<>"",Scoring!H31,"") -> 2 | C21: =IF(Scoring!H9<>"—",Scoring!H9,"") -> Real Estate Franchisee | D21: =IF(Scoring!H17<>"",Scoring!H17,"") -> 3.6 | E21: =IF(Scoring!H26<>"",Scoring!H26,"") -> 2.1 | F21: =IF(Scoring!H30<>"",Scoring!H30,"") -> 2.85 | G21: =IFERROR(INDEX('Risk Assessment'!$E$20:$I$20,1,MATCH(Scoring!H9,'Risk Assessment'!$E$9:$I$9,0)),"—") -> 🟡 Medium | H21: =IFERROR(INDEX('Risk Assessment'!$E$21:$I$21,1,MATCH(Scoring!H9,'Risk Assessment'!$E$9:$I$9,0)),"—") -> Supervised Execution | I21: =IF(F21="","",IF(F21>=4,IF(OR(G21="—",G21=""),"✅ Pursue",IF(ISNUMBER(SEARCH("Low",G21)),"✅ Pursue",IF(ISNUMBER(SEARCH("Medium",G21)),"✅ Pursue (Supervised)","⚠️ Investigate — mitigate risk"))),IF(F21>=3,IF(OR(G21="—",G21=""),"🔍 Investigate",IF(ISNUMBER(SEARCH("High",G21)),"⏸️ Park — risk too high","🔍 Investigate")),IF(F21>=2,"⏸️ Park","❌ Drop")))) -> ⏸️ Park | J21: =IF(F21="","",IF(OR(G21="—",G21=""),F21,IF(ISNUMBER(SEARCH("Low",G21)),F21*1,IF(ISNUMBER(SEARCH("Medium",G21)),F21*0.85,F21*0.7)))) -> 2.4225 | K21: =IF(J21="","",RANK(J21,$J$18:$J$27,0)) -> 4
B22: =IF(Scoring!I30<>"",Scoring!I31,"") -> 6 | C22: =IF(Scoring!I9<>"—",Scoring!I9,"") -> Personal Calendar Aid | D22: =IF(Scoring!I17<>"",Scoring!I17,"") -> 3.1 | E22: =IF(Scoring!I26<>"",Scoring!I26,"") -> 1.95 | F22: =IF(Scoring!I30<>"",Scoring!I30,"") -> 2.525 | G22: =IFERROR(INDEX('Risk Assessment'!$E$20:$I$20,1,MATCH(Scoring!I9,'Risk Assessment'!$E$9:$I$9,0)),"—") -> — | H22: =IFERROR(INDEX('Risk Assessment'!$E$21:$I$21,1,MATCH(Scoring!I9,'Risk Assessment'!$E$9:$I$9,0)),"—") -> — | I22: =IF(F22="","",IF(F22>=4,IF(OR(G22="—",G22=""),"✅ Pursue",IF(ISNUMBER(SEARCH("Low",G22)),"✅ Pursue",IF(ISNUMBER(SEARCH("Medium",G22)),"✅ Pursue (Supervised)","⚠️ Investigate — mitigate risk"))),IF(F22>=3,IF(OR(G22="—",G22=""),"🔍 Investigate",IF(ISNUMBER(SEARCH("High",G22)),"⏸️ Park — risk too high","🔍 Investigate")),IF(F22>=2,"⏸️ Park","❌ Drop")))) -> ⏸️ Park | J22: =IF(F22="","",IF(OR(G22="—",G22=""),F22,IF(ISNUMBER(SEARCH("Low",G22)),F22*1,IF(ISNUMBER(SEARCH("Medium",G22)),F22*0.85,F22*0.7)))) -> 2.525 | K22: =IF(J22="","",RANK(J22,$J$18:$J$27,0)) -> 3
B23: =IF(Scoring!J30<>"",Scoring!J31,"") -> 1 | C23: =IF(Scoring!J9<>"—",Scoring!J9,"") -> Travel Agent | D23: =IF(Scoring!J17<>"",Scoring!J17,"") -> 3.75 | E23: =IF(Scoring!J26<>"",Scoring!J26,"") -> 2.35 | F23: =IF(Scoring!J30<>"",Scoring!J30,"") -> 3.05 | G23: =IFERROR(INDEX('Risk Assessment'!$E$20:$I$20,1,MATCH(Scoring!J9,'Risk Assessment'!$E$9:$I$9,0)),"—") -> 🟡 Medium | H23: =IFERROR(INDEX('Risk Assessment'!$E$21:$I$21,1,MATCH(Scoring!J9,'Risk Assessment'!$E$9:$I$9,0)),"—") -> Supervised Execution | I23: =IF(F23="","",IF(F23>=4,IF(OR(G23="—",G23=""),"✅ Pursue",IF(ISNUMBER(SEARCH("Low",G23)),"✅ Pursue",IF(ISNUMBER(SEARCH("Medium",G23)),"✅ Pursue (Supervised)","⚠️ Investigate — mitigate risk"))),IF(F23>=3,IF(OR(G23="—",G23=""),"🔍 Investigate",IF(ISNUMBER(SEARCH("High",G23)),"⏸️ Park — risk too high","🔍 Investigate")),IF(F23>=2,"⏸️ Park","❌ Drop")))) -> 🔍 Investigate | J23: =IF(F23="","",IF(OR(G23="—",G23=""),F23,IF(ISNUMBER(SEARCH("Low",G23)),F23*1,IF(ISNUMBER(SEARCH("Medium",G23)),F23*0.85,F23*0.7)))) -> 2.5925 | K23: =IF(J23="","",RANK(J23,$J$18:$J$27,0)) -> 2
B24: =IF(Scoring!K30<>"",Scoring!K31,"") | C24: =IF(Scoring!K9<>"—",Scoring!K9,"") | D24: =IF(Scoring!K17<>"",Scoring!K17,"") | E24: =IF(Scoring!K26<>"",Scoring!K26,"") | F24: =IF(Scoring!K30<>"",Scoring!K30,"") | G24: =IFERROR(INDEX('Risk Assessment'!$E$20:$I$20,1,MATCH(Scoring!K9,'Risk Assessment'!$E$9:$I$9,0)),"—") -> — | H24: =IFERROR(INDEX('Risk Assessment'!$E$21:$I$21,1,MATCH(Scoring!K9,'Risk Assessment'!$E$9:$I$9,0)),"—") -> — | I24: =IF(F24="","",IF(F24>=4,IF(OR(G24="—",G24=""),"✅ Pursue",IF(ISNUMBER(SEARCH("Low",G24)),"✅ Pursue",IF(ISNUMBER(SEARCH("Medium",G24)),"✅ Pursue (Supervised)","⚠️ Investigate — mitigate risk"))),IF(F24>=3,IF(OR(G24="—",G24=""),"🔍 Investigate",IF(ISNUMBER(SEARCH("High",G24)),"⏸️ Park — risk too high","🔍 Investigate")),IF(F24>=2,"⏸️ Park","❌ Drop")))) | J24: =IF(F24="","",IF(OR(G24="—",G24=""),F24,IF(ISNUMBER(SEARCH("Low",G24)),F24*1,IF(ISNUMBER(SEARCH("Medium",G24)),F24*0.85,F24*0.7)))) | K24: =IF(J24="","",RANK(J24,$J$18:$J$27,0))
B25: =IF(Scoring!L30<>"",Scoring!L31,"") | C25: =IF(Scoring!L9<>"—",Scoring!L9,"") | D25: =IF(Scoring!L17<>"",Scoring!L17,"") | E25: =IF(Scoring!L26<>"",Scoring!L26,"") | F25: =IF(Scoring!L30<>"",Scoring!L30,"") | G25: =IFERROR(INDEX('Risk Assessment'!$E$20:$I$20,1,MATCH(Scoring!L9,'Risk Assessment'!$E$9:$I$9,0)),"—") -> — | H25: =IFERROR(INDEX('Risk Assessment'!$E$21:$I$21,1,MATCH(Scoring!L9,'Risk Assessment'!$E$9:$I$9,0)),"—") -> — | I25: =IF(F25="","",IF(F25>=4,IF(OR(G25="—",G25=""),"✅ Pursue",IF(ISNUMBER(SEARCH("Low",G25)),"✅ Pursue",IF(ISNUMBER(SEARCH("Medium",G25)),"✅ Pursue (Supervised)","⚠️ Investigate — mitigate risk"))),IF(F25>=3,IF(OR(G25="—",G25=""),"🔍 Investigate",IF(ISNUMBER(SEARCH("High",G25)),"⏸️ Park — risk too high","🔍 Investigate")),IF(F25>=2,"⏸️ Park","❌ Drop")))) | J25: =IF(F25="","",IF(OR(G25="—",G25=""),F25,IF(ISNUMBER(SEARCH("Low",G25)),F25*1,IF(ISNUMBER(SEARCH("Medium",G25)),F25*0.85,F25*0.7)))) | K25: =IF(J25="","",RANK(J25,$J$18:$J$27,0))
B26: =IF(Scoring!M30<>"",Scoring!M31,"") | C26: =IF(Scoring!M9<>"—",Scoring!M9,"") | D26: =IF(Scoring!M17<>"",Scoring!M17,"") | E26: =IF(Scoring!M26<>"",Scoring!M26,"") | F26: =IF(Scoring!M30<>"",Scoring!M30,"") | G26: =IFERROR(INDEX('Risk Assessment'!$E$20:$I$20,1,MATCH(Scoring!M9,'Risk Assessment'!$E$9:$I$9,0)),"—") -> — | H26: =IFERROR(INDEX('Risk Assessment'!$E$21:$I$21,1,MATCH(Scoring!M9,'Risk Assessment'!$E$9:$I$9,0)),"—") -> — | I26: =IF(F26="","",IF(F26>=4,IF(OR(G26="—",G26=""),"✅ Pursue",IF(ISNUMBER(SEARCH("Low",G26)),"✅ Pursue",IF(ISNUMBER(SEARCH("Medium",G26)),"✅ Pursue (Supervised)","⚠️ Investigate — mitigate risk"))),IF(F26>=3,IF(OR(G26="—",G26=""),"🔍 Investigate",IF(ISNUMBER(SEARCH("High",G26)),"⏸️ Park — risk too high","🔍 Investigate")),IF(F26>=2,"⏸️ Park","❌ Drop")))) | J26: =IF(F26="","",IF(OR(G26="—",G26=""),F26,IF(ISNUMBER(SEARCH("Low",G26)),F26*1,IF(ISNUMBER(SEARCH("Medium",G26)),F26*0.85,F26*0.7)))) | K26: =IF(J26="","",RANK(J26,$J$18:$J$27,0))
B27: =IF(Scoring!N30<>"",Scoring!N31,"") | C27: =IF(Scoring!N9<>"—",Scoring!N9,"") | D27: =IF(Scoring!N17<>"",Scoring!N17,"") | E27: =IF(Scoring!N26<>"",Scoring!N26,"") | F27: =IF(Scoring!N30<>"",Scoring!N30,"") | G27: =IFERROR(INDEX('Risk Assessment'!$E$20:$I$20,1,MATCH(Scoring!N9,'Risk Assessment'!$E$9:$I$9,0)),"—") -> — | H27: =IFERROR(INDEX('Risk Assessment'!$E$21:$I$21,1,MATCH(Scoring!N9,'Risk Assessment'!$E$9:$I$9,0)),"—") -> — | I27: =IF(F27="","",IF(F27>=4,IF(OR(G27="—",G27=""),"✅ Pursue",IF(ISNUMBER(SEARCH("Low",G27)),"✅ Pursue",IF(ISNUMBER(SEARCH("Medium",G27)),"✅ Pursue (Supervised)","⚠️ Investigate — mitigate risk"))),IF(F27>=3,IF(OR(G27="—",G27=""),"🔍 Investigate",IF(ISNUMBER(SEARCH("High",G27)),"⏸️ Park — risk too high","🔍 Investigate")),IF(F27>=2,"⏸️ Park","❌ Drop")))) | J27: =IF(F27="","",IF(OR(G27="—",G27=""),F27,IF(ISNUMBER(SEARCH("Low",G27)),F27*1,IF(ISNUMBER(SEARCH("Medium",G27)),F27*0.85,F27*0.7)))) | K27: =IF(J27="","",RANK(J27,$J$18:$J$27,0))
B29: How to use this table: The ADJUSTED RANK (column K) is your primary decision guide — it factors in risk. Risk-Adjusted Score = Composite × Risk Multiplier (Low = 1.0×, Medium = 0.85×, High = 0.70×). This means a 4.40 composite with High risk (4.40 × 0.70 = 3.08) ranks below a 3.83 composite with Low risk (3.83 × 1.0 = 3.83). The teaching: the highest-scoring use case isn't always the one you should build FIRST. The one with the best score-to-risk ratio is your safest path to early value. Recommendations: ✅ Pursue = high score + low risk — build it. ✅ Pursue (Supervised) = high score + medium risk — build with human oversight. ⚠️ Investigate — mitigate risk = high score + high risk — solve the risk first. 🔍 Investigate = moderate score — identify which dimension to improve. ⏸️ Park = not ready or risk too high. ❌ Drop = math doesn't work.

Sheet Ref
A1: F1 | B1: F2 | C1: F3 | D1: F4 | E1: F5 | F1: I1 | G1: I2 | H1: I3 | I1: I4 | J1: I5 | K1: R1 | L1: R2 | M1: R3 | N1: R4 | O1: R5 | P1: R6 | Q1: R7
A2: 1 — Nice to have, no sponsor | B2: 1 — Data doesn't exist yet | C2: 1 — Requires capabilities that don't exist | D2: 1 — Needs full autonomy but consequences are severe | E2: 1 — Months of work before any value | F2: 1 — Less than 2 hrs/week saved | G2: 1 — Negligible cost savings | H2: 1 — Errors are rare or inconsequential | I2: 1 — No revenue connection | J2: 1 — Benefits limited to one person | K2: 1 — Errors are easily corrected, no real harm | L2: 1 — Public data only | M2: 1 — No regulatory requirements | N2: 1 — Team is ready and eager | O2: 1 — Outputs are verifiable (code, math) | P2: 1 — Single system, stable API | Q2: 1 — Stable environment, rarely changes
A3: 2 — Loosely connected to a goal | B3: 2 — Data exists but needs major cleanup | C3: 2 — Significant R&D or custom work needed | D3: 2 — Autonomy/risk mismatch, hard to govern | E3: 2 — Results in 2–3 months | F3: 2 — 2–5 hrs/week saved | G3: 2 — Under $25K/year | H3: 2 — Occasional errors, minor impact | I3: 2 — Indirect revenue support | J3: 2 — Benefits a small team (2–5) | K3: 2 — Minor inconvenience or rework | L3: 2 — Internal, non-sensitive data | M3: 2 — Light compliance (internal policies) | N3: 2 — Some skills gaps, willing to learn | O3: 2 — Mostly verifiable with spot checks | P3: 2 — 2 systems, well-documented APIs | Q3: 2 — Changes quarterly, predictable
A4: 3 — Supports a known business goal | B4: 3 — Data exists, some integration needed | C4: 3 — Buildable but needs new tools/skills | D4: 3 — Moderate autonomy, manageable oversight | E4: 3 — Results in 4–6 weeks | F4: 3 — 5–15 hrs/week saved | G4: 3 — $25K–$75K/year | H4: 3 — Regular errors with moderate cost | I4: 3 — Enables faster revenue cycles | J4: 3 — Benefits a department (10–50) | K4: 3 — Moderate cost or customer impact | L4: 3 — Some personal or business-sensitive data | M4: 3 — Industry standards (SOC 2, ISO) | N4: 3 — Moderate gaps in skills or infrastructure | O4: 3 — Some outputs hard to verify | P4: 3 — 3–4 systems, some API fragility | Q4: 3 — Changes monthly, mostly manageable
A5: 4 — Directly tied to a priority | B5: 4 — Data accessible, APIs mostly ready | C5: 4 — Buildable with current tools, some effort | D5: 4 — Good autonomy fit with clear guardrails | E5: 4 — Demo-ready in 2–3 weeks | F5: 4 — 15–30 hrs/week saved | G5: 4 — $75K–$200K/year | H5: 4 — Frequent errors with real consequences | I5: 4 — Directly accelerates revenue | J5: 4 — Benefits across the organization | K5: 4 — Significant financial or trust damage | L5: 4 — PII, financial records, or health data | M5: 4 — Sector regulation (HIPAA, PCI) | N5: 4 — Significant cultural or technical barriers | O5: 4 — Many outputs require expert validation | P5: 4 — 5+ systems, mixed API quality | Q5: 4 — Changes frequently, hard to track
A6: 5 — Top-3 strategic initiative | B6: 5 — Clean data, APIs ready, integrations exist | C6: 5 — Could prototype in 1–2 weeks | D6: 5 — Low-risk task, full autonomy is safe | E6: 5 — Working prototype in days | F6: 5 — 30+ hrs/week saved | G6: 5 — Over $200K/year | H6: 5 — High error rate with severe consequences | I6: 5 — Opens new revenue streams | J6: 5 — Scales to 100+ users or processes | K6: 5 — Legal, safety, or severe financial harm | L6: 5 — Highly regulated or classified data | M6: 5 — Heavy regulation (GDPR+HIPAA, financial) | N6: 5 — Organization is not ready for this | O6: 5 — Errors indistinguishable from correct output | P6: 5 — Many systems, brittle or undocumented APIs | Q6: 5 — Constant flux, agent breaks without maintenance

Sheet Selection Brief
B2: Step 5: Selection Brief
B3: The decision document for your winning use case. Fill this in, then decide GO or NO-GO.
B5: This is the final output — a one-page brief for your chosen use case. Several fields auto-populate from earlier tabs. Where you see green cells with formulas, the value is calculated for you. Blue cells are your inputs.
B7: The Problem
B9: Use Case Name | C9: =IFERROR(INDEX('Prioritization Matrix'!$C$18:$C$27,MATCH(2,'Prioritization Matrix'!$K$18:$K$27,0)),"Enter name here") -> Travel Agent | D9: Auto-filled from your #1 RISK-ADJUSTED rank — the best candidate to build first. | E9: This pulls the use case with Adjusted Rank #1 from the Prioritization Matrix. The adjusted rank factors in risk — so a lower-composite but safer use case may rank above a high-composite but risky one. Override this by typing a different name if you have strategic reasons to choose differently.
B10: Discovery Pattern | C10: P8 — Repeated Analysis | D10: Which of the 10 patterns does this come from? Determines your tool chain. | E10: Which of the 10 discovery patterns (P1–P10) this comes from. This determines which tools and building blocks you'll need.
B11: Problem Statement | C11: Enjoyable travel breaks | D11: What specific problem does this solve? Who experiences it? 2–3 sentences. | E11: Describe the pain in plain language. Anyone reading this should immediately understand why it matters.
B12: Who It Affects | C12: Customers, Business and Sales | D12: Organization-wide (200+) | E12: Name the specific people or roles. The more concrete, the easier it is to measure success later.
B13: Current State | C13: Customers do independent analysis | D13: Walk through the manual steps. How is this done today? | E13: Walk through the manual process step by step. This becomes your 'before' picture for measuring improvement.
B14: Hours Consumed / Week | C14: 5 | D14: Total person-hours across ALL affected people per week. | E14: Total person-hours per week across ALL people who touch this process. If 3 people each spend 5 hrs, enter 15. This is a weekly figure.
B15: Fully Loaded Cost / Hour | C15: 50 | D15: HOURLY rate. Avg fully loaded cost per person per hour. Knowledge workers: typically $75–$150/hr. | E15: This is the HOURLY cost per person including salary, benefits, taxes, and overhead. A $75K/year employee costs roughly $50–$60/hr fully loaded. Senior knowledge workers: $100–$150/hr.
B16: Annual Cost of Current State | C16: =IF(OR(C14="",C15=""),"Enter hours and cost above",C14*C15*52) -> 13000 | D16: Auto-calculated: Hours/week × Cost/hour × 52 weeks | E16: Auto-calculated: Hours/week × Hourly cost × 52 weeks = your annual spend on this problem. This is the ceiling for your ROI.
B17: Error Rate (current process) | C17: 3 | D17: Enter the NUMBER only (e.g. 5 means 5%). Select N/A if not applicable. | E17: What percentage of outputs have errors today? Even 5% on high-volume tasks compounds fast.
B18: Cost Per Error | C18: 25 | D18: Cost per error in dollars. Select N/A if not applicable. | E18: What does each error cost in rework, penalties, customer churn, or lost deals? Can range from $10 (simple rework) to $10K+ (compliance violation).
B19: Annual Error Cost | C19: =IF(OR(C17="",C17="N/A",C18="",C18="N/A"),0,C14*52*(C17/100)*C18) -> 195 | D19: Auto-calculated: Hours/week × 52 × Error Rate × Cost Per Error | E19: Annual cost of errors in the current process. With 20 hrs/week, 5% error rate, $100/error: 20 × 52 × 0.05 × $100 = $5,200/year.
B20: Total Annual Cost (incl. errors) | C20: =IF(C16="Enter hours and cost above","—",C16+C19) -> 13195 | D20: Auto-calculated: Annual Labor Cost + Annual Error Cost | E20: Your TRUE annual cost of the current state — labor plus error impact. Both are annual figures. This is your ROI baseline.
B22: The Agent Approach
B24: What the Agent Will Do | C24: Agent will plan the travel like an expert | D24: Describe in plain language — not technical specs. What does the user experience? | E24: Describe the agent's job in plain language — what it does, not how it's built. Focus on the user experience.
B25: Key Building Blocks | C25: LLM + Loop + Tools + Skills + Memory + Guardrails | D25: Select the combination that fits. See the 8 blocks in the Primer. | E25: Which of the 8 building blocks from the Primer. The pattern you selected in Discovery tab suggests the right combination.
B26: Tools & MCP Integrations | D26: Select primary tool chain. Add specific MCP servers (Gmail, Slack, GitHub, etc.) in the text. | E26: List the specific systems the agent connects to. Check your pattern's Arsenal in the Discovery tab for suggested tool chains.
B27: Autonomy Level | C27: =IFERROR(INDEX('Risk Assessment'!$E$21:$I$21,1,MATCH(C9,'Risk Assessment'!$E$9:$I$9,0)),"Score Risk Assessment first") -> Supervised Execution | D27: Auto-filled from Risk Assessment. Full Autonomy / Supervised / Human-Required. | E27: Auto-filled from your Risk Assessment. Determines how much human oversight is needed.
B28: Success Criteria | D28: 2–3 measurable outcomes. How will you know this worked? | E28: Define 2–3 measurable outcomes. 'Reduce ticket triage time from 6 hrs/day to 1 hr/day' is better than 'improve efficiency.'
B29: Primary Risk | D29: Select the biggest risk. These are the most common in AI agent systems. | E29: The single biggest thing that could derail this. Agent-specific risks (hallucination, MCP failure, drift) are the most commonly underestimated.
B30: Mitigation Plan | D30: How will you handle this risk? Be specific. | E30: How will you handle the primary risk? Be specific: 'Add human review for all outputs above $1K' not 'monitor carefully.'
B32: Preliminary ROI Estimate
B33: This is a back-of-napkin estimate to answer: "Is this worth pursuing?" For a full financial model with token costs, infra pricing, and multi-year projections, use the ROI & Business Case Calculator — a separate deliverable on agenticstrategylab.com.
B35: Current Annual Cost | C35: =IF(C20="—","—",C20) -> 13195 | D35: From The Problem section — now includes error costs. | E35: Includes both labor cost and error cost. This is your true baseline for ROI calculation.
B36: Expected Automation Rate | D36: Select a number (e.g. 50 = 50%). 50–70% realistic for v1 agents. | E36: What % of the work can the agent handle? 50–70% is realistic for a v1 agent. 30% is conservative. 90% is rare outside simple tasks.
B37: Annual Value of Automation | C37: =IF(OR(C35="—",C36=""),"—",C35*(C36/100)) -> — | D37: Auto-calculated: Annual Cost × Automation Rate | E37: Auto-calculated: Annual Cost × Automation Rate. This is your gross annual benefit before agent costs.
B38: Estimated Build Cost | D38: ONE-TIME cost. Engineering + tools + infra to build and deploy. | E38: One-time cost to build and deploy. Includes engineering time, tool licenses, and infrastructure setup. This is NOT annual — it's the upfront investment.
B39: Estimated Annual Run Cost | D39: ANNUAL cost. API tokens + hosting + monitoring + maintenance per year. | E39: Recurring yearly cost: API token usage, cloud hosting, monitoring tools, and ongoing maintenance. This IS annual.
